<!DOCTYPE html>
<html lang="en">
<head>
    <meta charset="UTF-8">
    <meta name="viewport" content="width=device-width, initial-scale=1.0">
    <meta http-equiv="X-UA-Compatible" content="ie=edge">
    <title>Document</title>
</head>
<body>
    
</body>
<script>

//异常处理基本形式
// try语句包含了由一个或者多个语句组成的try块, 和至少一个catch子句或者一个finally子句的其中一个
// 或者两个兼有， 下面是三种形式的try声明:
// try...catch
// try...finally
// try...catch...finally
try{
    //try_statements 可能出现错误部分
    console.log("try_statements");
    throw "Some Error";//可以抛出异常 throw new Error("ErrorMsg");
    // var a= new Array(-1);
    // throw new TypeError();// throw new ReferenceError();
}
catch(e){ //catch和finally至少有一个
    //catch_statements 捕获处理异常
    console.warn("catch_statements",e);
}
finally{ //catch和finally至少有一个
    //finally_statements 最终处理
    console.log("finally_statements");
}

/*
catch语句中包含要执行的语句，当try语句中抛出错误时。
也就是，你想让try语句中的内容成功， 如果没成功，你想控制接下来发生的事情，这时你可以在catch语句中实现。
如果有在try块中有任何一个语句（或者从try块中调用的函数）抛出异常, 控制立即转向catch子句。
如果在try块中没有异常抛出，则catch子句将会跳过。
finally子句无论是否有异常抛出或着是否被捕获它总是执行。
可以嵌套一个或者更多的try语句,如果内部的try语句没有catch子句，那么将会进入包围它的try语句的catch子句。
 */
try {
    try{
        throw "ErrorMessage11";
    }
    // catch (e){
    //     //throw "ErrorMessage22"; //抛出异常后将直接跳出catch，catch内后续代码不再执行
    //     console.log("inside catch",e);
    //     //throw "ErrorMessage22";
    // }
    finally {
        console.log("finally 111");
    }
}
catch (e) {
    console.log("outside catch",e);
}
finally {
    console.log("finally 222");
}


//关于console
console.log("logInfo");
console.warn("warnInfo");
console.error("errorInfo");
console.assert(3>2,"有问题的话会输出这句话11111");
console.assert(2==="2","有问题的话会输出这句话22222");


//Part 22222222222222 嵌套的 try-blocks
//1
try {
    try {
        throw "oops";
    }
    finally {
        console.log("finally");
    }
}
catch (ex) {
    console.error("outer", ex);
}
// Output:
// "finally"
// "outer" "oops"

//2
try {
    try {
        throw "oops";
    }
    catch (ex) {
        console.error("inner", ex);
    }
    finally {
        console.log("finally");
    }
}
catch (ex) {
    console.error("outer", ex);
}
// Output:
// "inner" "oops"
// "finally"

//3
try {
    try {
        throw "oops";
    }
    catch (ex) {
        console.error("inner", ex);
        throw ex;
    }
    finally {
        console.log("finally");
    }
}
catch (ex) {
    console.error("outer", ex);
}
// Output:
// "inner" "oops"
// "finally"
// "outer" "oops"

//4
try {
    try {
        throw "oops";
    }
    catch (ex) {
        console.warn("inner", ex);
        throw ex;
    }
    finally {
        console.log("finally");
    }
}
catch (ex) {
    console.warn("outer", ex);
}
// Output:
// "inner" "oops"
// "finally"

//Part33333333333333
//思考下述两段代码的区别，思考两者调用栈CallStack的不同
try{
	function abc(x,cb){
		console.log(x);
		cb();
    }
	abc("xx",function(){
		var arr = new Array(-1);
	});
}
catch(e){
	console.log(e);
}

//JS的异步
//思考这种情况是否能捕获到异常，回调函数捕获异常的问题
try{
	function abc(x,cb){
		console.log(x);
		cb();
    }
}
catch(e){
	console.log(e);
}
abc("xx",function(){
    var arr = new Array(-1);
});



 window.onload = function () {
    window.Foo = function () {
        var inputValue = document.getElementById("inputID").value;
        try{
            var n = parseInt(inputValue);
            var a= new Array(n);//定义一个数组 传3试试、再传-5试试
            for(var i=0;i<n;i++){a[i] = i;}
        }
        catch(e){
            alert(e.name+e.message);
            console.log("n:",n);
            a = [];
        }
        finally {
            document.getElementById("labelID").innerHTML = a+"_"+(a instanceof Array)
        }
    };
};


/**
 * Created by qile on 2017/8/14.
 */
//Error相关
var e1 = new Error("e1 Error Msg");
try {
    throw  e1;//throw new Error("Whoops!");
} catch (e) {
    console.log(e.name + ": " + e.message);
}

//可以直接创建Error对象
console.log(Error.prototype);//{name: "Error", message: "", constructor: function, toString: function}
var myError = new Error("NewMessage");
console.log(myError.name,myError.message);

////基于Error的子类，可以创建自定义错误对象，并添加若干自有属性
function MyError(name,message) {
    this.name = name||'MyError';
    this.message = message || 'Default Message';
}
MyError.prototype.__proto__ = Error.prototype;
//MyError.prototype = Object.create(Error.prototype);
//MyError.prototype.constructor = MyError;


try {
    // throw new MyError();
    throw new MyError('custom message');
} catch (e) {
    console.log(e.name);     // 'MyError'
    console.log(e.message);  // 'custom message'
}


try
{
    var x = y;// 没有定义y所以产生错误。如果有y的话，不会抛异常错误
    //console.log("x") = 23;//赋值引用错误，在chorme中测试
}catch(e){
    console.log(e.name,e.message);
}
finally {
    console.log("finally");//有无异常该句都会执行
}

//Part 222222222 范围错误 RangeError
try{
    var a= new Array(-1);
    //var a= new Array(1);
}catch(e){
    console.log(e.name,e.message);
}
finally {
    console.log("finally");//有无异常该句都会执行
}

//Part 3333333333 类型错误 TypeError
try{
    var a;a.aa();
    //var a= new 123; //在chrome中测试
}catch(e){
    console.log(e.name,e.message);
}
finally {
    console.log("finally");//有无异常该句都会执行
}

//自定义错误类
function UserError(message,name){
    this.message = message || '默认信息';
    this.name = name || 'UserError';
}
UserError.prototype.__proto__ = Error.prototype;
// UserError.prototype = new Error();
// UserError.prototype.constructor = UserError;


//错误类型测试
try {
    throw new RangeError();
    // throw new TypeError();
    // throw new ReferenceError();
} catch (e) {
    if (e instanceof TypeError) {
        console.log("TypeError");
    } else if (e instanceof RangeError) {
        console.log("RangeError");
    } else if (e instanceof ReferenceError) {
        console.log("ReferenceError");
    } else {
        console.log("OtherError");
    }
}

//
try {
    throw n; // 抛出一个数值异常
} catch (e) {
    if (e <= 50) {
        // 异常在 1-50 之间时，直接处理
    } else {
        // 异常无法处理，重新抛出，可再外层再次被捕获
        throw e;
    }
}


//自定义错误
//输入月份异常案例 注意可以在外层进行捕获异常错误
function UserException(message) {
    this.message = message;
    this.name = "UserException";
}
UserException.prototype.__proto__ = Error.prototype;
function getMonthName(mo) {
    mo = mo-1; // 调整月份数字到数组索引 (1=Jan, 12=Dec)
    var months = ["Jan", "Feb", "Mar", "Apr", "May", "Jun", "Jul",
        "Aug", "Sep", "Oct", "Nov", "Dec"];
    if (months[mo] !== undefined) {
        return months[mo];
    } else {
        throw new UserException("InvalidMonthNo");
    }
}
try {
    // statements to try
    var myMonth = 15; // 15 超出边界并引发异常 试试改成8
    var monthName = getMonthName(myMonth);
} catch (e) {
    var monthName = "unknown";
    console.log(e.message, e.name); // 传递异常对象到错误处理
}




</script>
</html>